<?xml version="1.0"?>
<robot name="simple_robot">
  <!-- ROS 2 conversion of simple_robot -->
  <!-- Key changes:
       1. Added ros2_control plugin for hardware interface
       2. Updated Gazebo plugins for ROS 2 compatibility
       3. Added frame transformations for standard ROS 2 frames
  -->

  <!-- Base footprint is a virtual link representing the ground contact point -->
  <link name="base_footprint"/>

  <!-- Fixed joint connecting base_footprint to base_link -->
  <joint name="base_joint" type="fixed">
    <origin xyz="0 0 0.1" rpy="0 0 0"/>
    <parent link="base_footprint"/>
    <child link="base_link"/>
  </joint>

  <!-- Main robot body -->
  <link name="base_link">
    <visual>
      <geometry>
        <box size="0.3 0.2 0.1"/>
      </geometry>
      <material name="blue">
        <color rgba="0 0 1 1"/>
      </material>
    </visual>
    <collision>
      <geometry>
        <box size="0.3 0.2 0.1"/>
      </geometry>
    </collision>
    <inertial>
      <mass value="1.0"/>
      <inertia ixx="0.01" ixy="0.0" ixz="0.0" iyy="0.01" iyz="0.0" izz="0.01"/>
    </inertial>
  </link>

  <!-- Left wheel -->
  <joint name="left_wheel_joint" type="continuous">
    <parent link="base_link"/>
    <child link="left_wheel"/>
    <origin xyz="0 0.12 0" rpy="1.5708 0 0"/>
    <axis xyz="0 0 1"/>
  </joint>

  <link name="left_wheel">
    <visual>
      <geometry>
        <cylinder radius="0.05" length="0.02"/>
      </geometry>
      <material name="black">
        <color rgba="0 0 0 1"/>
      </material>
    </visual>
    <collision>
      <geometry>
        <cylinder radius="0.05" length="0.02"/>
      </geometry>
    </collision>
    <inertial>
      <mass value="0.1"/>
      <inertia ixx="0.001" ixy="0.0" ixz="0.0" iyy="0.001" iyz="0.0" izz="0.001"/>
    </inertial>
  </link>

  <!-- Right wheel -->
  <joint name="right_wheel_joint" type="continuous">
    <parent link="base_link"/>
    <child link="right_wheel"/>
    <origin xyz="0 -0.12 0" rpy="1.5708 0 0"/>
    <axis xyz="0 0 1"/>
  </joint>

  <link name="right_wheel">
    <visual>
      <geometry>
        <cylinder radius="0.05" length="0.02"/>
      </geometry>
      <material name="black"/>
    </visual>
    <collision>
      <geometry>
        <cylinder radius="0.05" length="0.02"/>
      </geometry>
    </collision>
    <inertial>
      <mass value="0.1"/>
      <inertia ixx="0.001" ixy="0.0" ixz="0.0" iyy="0.001" iyz="0.0" izz="0.001"/>
    </inertial>
  </link>

  <!-- ROS 2 specific additions -->
  <!-- ros2_control plugin for hardware interface -->
  <ros2_control name="simple_robot_system" type="system">
    <hardware>
      <plugin>gz_ros2_control/GazeboSimSystem</plugin>
    </hardware>
    <joint name="left_wheel_joint">
      <command_interface name="velocity"/>
      <state_interface name="position"/>
      <state_interface name="velocity"/>
    </joint>
    <joint name="right_wheel_joint">
      <command_interface name="velocity"/>
      <state_interface name="position"/>
      <state_interface name="velocity"/>
    </joint>
  </ros2_control>

  <!-- Gazebo simulation enhancements for ROS 2 -->
  <gazebo>
    <plugin name="gz_ros2_control" filename="libgz_ros2_control-system.so">
      <parameters>/home/user/my_robot/config/simple_robot_controllers.yaml</parameters>
    </plugin>
  </gazebo>
</robot>