<?xml version="1.0"?>
<robot name="simple_robot" xmlns:xacro="http://www.ros.org/wiki/xacro">

  <!-- Properties -->
  <xacro:property name="wheel_radius" value="0.05" />
  <xacro:property name="wheel_width" value="0.02" />
  <xacro:property name="wheel_separation" value="0.24" />

  <!-- Base footprint -->
  <link name="base_footprint"/>

  <!-- Base joint -->
  <joint name="base_joint" type="fixed">
    <origin xyz="0 0 0.1" rpy="0 0 0"/>
    <parent link="base_footprint"/>
    <child link="base_link"/>
  </joint>

  <!-- Base link -->
  <link name="base_link">
    <visual>
      <geometry>
        <box size="0.3 0.2 0.1"/>
      </geometry>
      <material name="blue">
        <color rgba="0 0 1 1"/>
      </material>
    </visual>
    <collision>
      <geometry>
        <box size="0.3 0.2 0.1"/>
      </geometry>
    </collision>
    <inertial>
      <mass value="1.0"/>
      <inertia ixx="0.01" ixy="0.0" ixz="0.0" iyy="0.01" iyz="0.0" izz="0.01"/>
    </inertial>
  </link>

  <!-- Wheel macro -->
  <xacro:macro name="wheel" params="prefix y_offset">
    <joint name="${prefix}_wheel_joint" type="continuous">
      <parent link="base_link"/>
      <child link="${prefix}_wheel"/>
      <origin xyz="0 ${y_offset} 0" rpy="1.5708 0 0"/>
      <axis xyz="0 0 1"/>
    </joint>

    <link name="${prefix}_wheel">
      <visual>
        <geometry>
          <cylinder radius="${wheel_radius}" length="${wheel_width}"/>
        </geometry>
        <material name="black">
          <color rgba="0 0 0 1"/>
        </material>
      </visual>
      <collision>
        <geometry>
          <cylinder radius="${wheel_radius}" length="${wheel_width}"/>
        </geometry>
      </collision>
      <inertial>
        <mass value="0.1"/>
        <inertia ixx="0.001" ixy="0.0" ixz="0.0" iyy="0.001" iyz="0.0" izz="0.001"/>
      </inertial>
    </link>
  </xacro:macro>

  <!-- Instantiate wheels -->
  <xacro:wheel prefix="left" y_offset="${wheel_separation/2}"/>
  <xacro:wheel prefix="right" y_offset="${-wheel_separation/2}"/>

  <!-- ROS 2 control interfaces -->
  <ros2_control name="simple_robot_system" type="system">
    <hardware>
      <plugin>gz_ros2_control/GazeboSimSystem</plugin>
    </hardware>
    <joint name="left_wheel_joint">
      <command_interface name="velocity"/>
      <state_interface name="position"/>
      <state_interface name="velocity"/>
    </joint>
    <joint name="right_wheel_joint">
      <command_interface name="velocity"/>
      <state_interface name="position"/>
      <state_interface name="velocity"/>
    </joint>
  </ros2_control>

  <!-- Gazebo plugins for ROS 2 -->
  <gazebo>
    <plugin name="gz_ros2_control" filename="libgz_ros2_control-system.so">
      <parameters>/home/user/my_robot/config/simple_robot_controllers.yaml</parameters>
    </plugin>
  </gazebo>

</robot>